<?xml version="1.0"?>
<robot name="1_dof_arm" xmlns:xacro="http://www.ros.org/wiki/xacro">

  <!-- Import all Gazebo-customization elements, including Gazebo colors -->
  <xacro:include filename="$(find wearable_robot_description)/urdf/1_dof_arm.gazebo"/>
  <!-- Import Rviz colors -->
  <xacro:include filename="$(find wearable_robot_description)/urdf/materials.xacro"/>

    <link name="world"/>

    <joint name="fixed" type="fixed">
        <parent link="world"/>
        <child link="base_link"/>
    </joint>

    <link name="base_link">
        <visual>
            <geometry>
                <cylinder length="0.4" radius="0.04"/>
            </geometry>
            <origin rpy="0 0 0" xyz="0 0 0.6"/>
            <material name="blue">
                <color rgba="0 0 1 1"/>
            </material>
        </visual>
        <collision>
            <geometry>
                <cylinder length="0.4" radius="0.06"/>
            </geometry>
            <origin rpy="0 0 0" xyz="0 0 0.6"/>
        </collision>

        <inertial>
            <mass value="1"/>
            <inertia ixx="1.0" ixy="0.0" ixz="0.0" iyy="1.0" iyz="0.0" izz="1.0"/>
        </inertial>
    </link>

    <joint name="arm_joint" type="revolute">
        <parent link="base_link"/>
        <child link="arm_link"/>
        <origin xyz="0 0 0.4"/>
        <axis xyz="0 1 0" />
        <limit effort="300" velocity="0.1" lower="4.71" upper="1.8"/>
        <dynamics damping="50" friction="1"/>
    </joint>

    <link name="arm_link">
        <visual>
            <geometry>
                <cylinder length="0.4" radius="0.04"/>
            </geometry>
            <origin rpy="0 1.570796 0" xyz="-0.16 0 0"/>
            <material name="red">
                <color rgba="1 0 0 1"/>
            </material>
        </visual>
        <collision>
            <geometry>
                <cylinder length="0.4" radius="0.06"/>
            </geometry>
            <origin rpy="0 1.570796 0" xyz="-0.16 0 0"/>
        </collision>

        <inertial>
            <mass value="1"/>
            <inertia ixx="1.0" ixy="0.0" ixz="0.0" iyy="1.0" iyz="0.0" izz="1.0"/>
        </inertial>
    </link>

  <ros2_control name="GazeboSystem" type="system">
    <hardware>
      <plugin>gazebo_ros2_control/GazeboSystem</plugin>
    </hardware>
    <joint name="arm_joint">
      <command_interface name="position">
        <param name="min">1.79</param>
        <param name="max">6.28</param>
      </command_interface>
      <state_interface name="position"/>
      <state_interface name="velocity"/>
      <state_interface name="effort"/>
    </joint>
  </ros2_control>
</robot>
