<?xml version="1.0"?>
<robot name="grip" xmlns:xacro="http://www.ros.org/wiki/xacro">
    <link name="world"/>

    <joint name="fixed" type="fixed">
        <parent link="world"/>
        <child link="poll"/>
    </joint>

    <link name="poll">
        <visual>
            <geometry>
                <cylinder length="1" radius="0.1"/>
            </geometry>
            <origin rpy="0 0 1.570796" xyz="0 0 0.5"/>
        </visual>
        <collision>
            <geometry>
                <cylinder length="1" radius="0.1"/>
            </geometry>
            <origin rpy="0 0 1.570796" xyz="0 0 0.5"/>
        </collision>
        <inertial>
            <mass value="1.0"/>
            <inertia ixx="1.0" ixy="0.0" ixz="0.0" iyy="1.0" iyz="0.0" izz="1.0"/>
        </inertial>
    </link>

    <joint name="box_to_poll" type="prismatic">
        <parent link="poll"/>
        <child link="box"/>
        <origin xyz="0.0 0.0 1.0"/>
        <axis xyz="0 0 1" />
        <limit effort="1000.0" lower="0" upper="2" velocity="30"/>
        <dynamics damping="0" friction="0"/>
    </joint>

    <link name="box">
        <visual>
            <geometry>
                <box size="0.1 0.1 0.1"/>
            </geometry>
            <origin rpy="0 0 0" xyz="0 0 0"/>
            <material name="red">
                <color rgba="1 0 0 1"/>
            </material>
        </visual>
        <collision>
            <geometry>
              <box size="0.1 0.1 0.1"/>
            </geometry>
            <origin rpy="0 0 0" xyz="0 0 0"/>
        </collision>
        <inertial>
            <mass value="1.0"/>
            <inertia ixx="1.0" ixy="0.0" ixz="0.0" iyy="1.0" iyz="0.0" izz="1.0"/>
        </inertial>
    </link>

  <ros2_control name="GazeboSystem" type="system">
    <hardware>
      <plugin>gazebo_ros2_control/GazeboSystem</plugin>
    </hardware>
    <joint name="box_to_poll">
      <command_interface name="effort">
        <param name="min">-1000</param>
        <param name="max">1000</param>
      </command_interface>
      <state_interface name="position">
        <param name="initial_value">1.0</param>
      </state_interface>
      <state_interface name="velocity"/>
      <state_interface name="effort"/>
    </joint>
  </ros2_control>

  <gazebo>
    <plugin filename="libgazebo_ros2_control.so" name="gazebo_ros2_control">
      <parameters>$(find wearable_robot_description)/config/grip.yaml</parameters>
    </plugin>
  </gazebo>

  <gazebo reference="poll">
    <mu1>1.01</mu1>
    <mu2>1.01</mu2>
    <self_collide>1</self_collide>
    <material>Gazebo/DarkGrey</material>
    <kp value="1000000.0"/>
    <kd value="1.0"/>
  </gazebo>

  <gazebo reference="box">
    <mu1>0.2</mu1>
    <mu2>0.2</mu2>
    <self_collide>1</self_collide>
    <material>Gazebo/Red</material>
    <kp value="1000000.0"/>
    <kd value="1.0"/>
  </gazebo>

</robot>
